<?xml version="1.0" encoding="utf-8"?>
<!-- This URDF was automatically created by SolidWorks to URDF Exporter! Originally created by Stephen Brawner (brawner@gmail.com) 
     Commit Version: 1.6.0-4-g7f85cfe  Build Version: 1.6.7995.38578
     For more information, please see http://wiki.ros.org/sw_urdf_exporter -->
<robot
  name="car_fix_wheels">
  <!-- <link name="world"/>
  <joint name="base_joint" type="fixed">
    <parent link="world"/>
    <child link="base_link"/>
    <origin rpy="0 0 0" xyz="0.0 0.0 0.17"/>
  </joint> -->
  <material name="gray">
    <color rgba="0.5 0.5 0.5 1.0"/>
  </material>
  <link
    name="base_link">
    <inertial>
      <origin
        xyz="0.00703460169417443 -1.90802063382289E-06 -0.00523072040334664"
        rpy="0 0 0" />
      <mass
        value="2" />
      <inertia
        ixx="1.19644424497777"
        ixy="-4.94231058876372E-10"
        ixz="-0.00760814181478402"
        iyy="4.11177635643324"
        iyz="1.04347758047462E-16"
        izz="5.03703438092778" />
    </inertial>
    <visual>
      <origin
        xyz="0 0 0"
        rpy="0 0 0" />
      <geometry>
        <mesh
          filename="package://car_fix_wheels/meshes/base_link.STL" />
      </geometry>
      <material
        name="">
        <color
          rgba="0.792156862745098 0.819607843137255 0.933333333333333 1" />
      </material>
    </visual>
    <collision>
      <origin
        xyz="0 0 0"
        rpy="0 0 0" />
      <geometry>
        <mesh
          filename="package://car_fix_wheels/meshes/base_link.STL" />
      </geometry>
    </collision>
  </link>
  <link
    name="link_1">
    <inertial>
      <origin
        xyz="1.11022302462516E-16 0.11647007944399 -2.77555756156289E-17"
        rpy="0 0 0" />
      <mass
        value="0.1" />
      <inertia
        ixx="0.0221939275547437"
        ixy="-8.99391945456366E-15"
        ixz="-1.73472347597681E-18"
        iyy="0.0117312495828615"
        iyz="-2.31813505111025E-19"
        izz="0.0181381446533186" />
    </inertial>
    <visual>
      <origin
        xyz="0 0 0"
        rpy="0 0 0" />
      <geometry>
        <mesh
          filename="package://car_fix_wheels/meshes/link_1.STL" />
      </geometry>
      <material
        name="">
        <color
          rgba="1 1 1 1" />
      </material>
    </visual>
    <collision>
      <origin
        xyz="0 0 0"
        rpy="0 0 0" />
      <geometry>
        <mesh
          filename="package://car_fix_wheels/meshes/link_1.STL" />
      </geometry>
    </collision>
  </link>
  <joint
    name="joint_1"
    type="revolute">
    <origin
      xyz="0 0 0.2"
      rpy="1.5707963267949 0 1.00897491790746" />
    <parent
      link="base_link" />
    <child
      link="link_1" />
    <axis
      xyz="0 1 0" />
    <limit
      lower="-3.14"
      upper="3.14"
      effort="300"
      velocity="3" />
  </joint>
  <link
    name="link_2">
    <inertial>
      <origin
        xyz="-5.33451061102141E-12 0.132502782788624 0.000356704762693366"
        rpy="0 0 0" />
      <mass
        value="0.1" />
      <inertia
        ixx="0.0487123203278302"
        ixy="-4.51222135285263E-13"
        ixz="-1.84210285913977E-14"
        iyy="0.00601145501077518"
        iyz="-6.68877031380326E-05"
        izz="0.0490592428788894" />
    </inertial>
    <visual>
      <origin
        xyz="0 0 0"
        rpy="0 0 0" />
      <geometry>
        <mesh
          filename="package://car_fix_wheels/meshes/link_2.STL" />
      </geometry>
      <material
        name="">
        <color
          rgba="0.792156862745098 0.819607843137255 0.933333333333333 1" />
      </material>
    </visual>
    <collision>
      <origin
        xyz="0 0 0"
        rpy="0 0 0" />
      <geometry>
        <mesh
          filename="package://car_fix_wheels/meshes/link_2.STL" />
      </geometry>
    </collision>
  </link>
  <joint
    name="joint_2"
    type="revolute">
    <origin
      xyz="0 0.205 0"
      rpy="0 0 0.0590472178971879" />
    <parent
      link="link_1" />
    <child
      link="link_2" />
    <axis
      xyz="0 0 1" />
    <limit
      lower="-2"
      upper="2"
      effort="200"
      velocity="3" />
  </joint>
  <link
    name="left_link_car">
    <inertial>
      <origin
        xyz="0 -0.0436842105263158 -6.93889390390723E-18"
        rpy="0 0 0" />
      <mass
        value="2" />
      <inertia
        ixx="0.0620059302577679"
        ixy="-1.0101680263708E-18"
        ixz="2.87299458492871E-18"
        iyy="0.10348003684366"
        iyz="-2.25475308254853E-18"
        izz="0.0620059302577679" />
    </inertial>
    <visual>
      <origin
        xyz="0 0 0"
        rpy="0 0 0" />
      <geometry>
        <mesh
          filename="package://car_fix_wheels/meshes/left_link_car.STL" />
      </geometry>
      <material
        name="">
        <color
          rgba="0.792156862745098 0.819607843137255 0.933333333333333 1" />
      </material>
    </visual>
    <collision>
      <origin
        xyz="0 0 0"
        rpy="0 0 0" />
      <geometry>
        <mesh
          filename="package://car_fix_wheels/meshes/left_link_car.STL" />
      </geometry>
    </collision>
  </link>
  <joint
    name="left_joint_car"
    type="continuous">
    <origin
      xyz="-0.300453997850607 0.294997459621556 -0.025"
      rpy="0 0 0" />
    <parent
      link="base_link" />
    <child
      link="left_link_car" />
    <axis
      xyz="0 1 0" />
    <limit
      effort="150"
      velocity="2" />
  </joint>
  <link
    name="right_link_car">
    <inertial>
      <origin
        xyz="0 0.0436842105263159 -6.93889390390723E-18"
        rpy="0 0 0" />
      <mass
        value="2" />
      <inertia
        ixx="0.0620059302577679"
        ixy="-2.73033766169638E-21"
        ixz="1.00605687834278E-33"
        iyy="0.10348003684366"
        iyz="-4.98679721566001E-18"
        izz="0.0620059302577679" />
    </inertial>
    <visual>
      <origin
        xyz="0 0 0"
        rpy="0 0 0" />
      <geometry>
        <mesh
          filename="package://car_fix_wheels/meshes/right_link_car.STL" />
      </geometry>
      <material
        name="">
        <color
          rgba="0.792156862745098 0.819607843137255 0.933333333333333 1" />
      </material>
    </visual>
    <collision>
      <origin
        xyz="0 0 0"
        rpy="0 0 0" />
      <geometry>
        <mesh
          filename="package://car_fix_wheels/meshes/right_link_car.STL" />
      </geometry>
    </collision>
  </link>
  <joint
    name="right_joint_car"
    type="continuous">
    <origin
      xyz="-0.300453997850607 -0.295002540378444 -0.025"
      rpy="0 0 0" />
    <parent
      link="base_link" />
    <child
      link="right_link_car" />
    <axis
      xyz="0 1 0" />
    <limit
      effort="150"
      velocity="2" />
  </joint>
  <link
    name="castor_link">
    <inertial>
      <origin
        xyz="0.00335948404407965 0.00189761350337025 -0.0155756588970051"
        rpy="0 0 0" />
      <mass
        value="1" />
      <inertia
        ixx="0.00231070236013653"
        ixy="-6.66279822450278E-06"
        ixz="5.31586564293953E-05"
        iyy="0.00231955231220187"
        iyz="2.84854037865837E-05"
        izz="0.00428998878470102" />
    </inertial>
    <visual>
      <origin
        xyz="0 0 0"
        rpy="0 0 0" />
      <geometry>
        <mesh
          filename="package://car_fix_wheels/meshes/castor_link.STL" />
      </geometry>
      <material
        name="">
        <color
          rgba="0.63921568627451 0.666666666666667 0.67843137254902 1" />
      </material>
    </visual>
    <collision>
      <origin
        xyz="0 0 0"
        rpy="0 0 0" />
      <geometry>
        <mesh
          filename="package://car_fix_wheels/meshes/castor_link.STL" />
      </geometry>
    </collision>
  </link>
  <joint
    name="castor_joint"
    type="continuous">
    <origin
      xyz="0.30757 0 -0.085"
      rpy="0 0 0" />
    <parent
      link="base_link" />
    <child
      link="castor_link" />
    <axis
      xyz="0 0 -1" />
    <limit
      lower="0"
      upper="0"
      effort="10"
      velocity="10" />
  </joint>
  <link
    name="castor_wheel_link">
    <inertial>
      <origin
        xyz="4.06328387603239E-09 -1.06080838557787E-11 -7.58418688961982E-09"
        rpy="0 0 0" />
      <mass
        value="1" />
      <inertia
        ixx="0.000175490456749465"
        ixy="-5.89693206856289E-15"
        ixz="-3.76119809348271E-05"
        iyy="0.00015534184502462"
        iyz="-1.25031914035428E-14"
        izz="0.000225553188836567" />
    </inertial>
    <visual>
      <origin
        xyz="0 0 0"
        rpy="0 0 0" />
      <geometry>
        <mesh
          filename="package://car_fix_wheels/meshes/castor_wheel_link.STL" />
      </geometry>
      <material
        name="">
        <color
          rgba="1 1 1 1" />
      </material>
    </visual>
    <collision>
      <origin
        xyz="0 0 0"
        rpy="0 0 0" />
      <geometry>
        <mesh
          filename="package://car_fix_wheels/meshes/castor_wheel_link.STL" />
      </geometry>
    </collision>
  </link>
  <joint
    name="castor_wheel_joint"
    type="continuous">
    <origin
      xyz="0.039706 0.02127 -0.06888"
      rpy="-1.5708 0 0" />
    <parent
      link="castor_link" />
    <child
      link="castor_wheel_link" />
    <axis
      xyz="-0.47221 0 0.88149" />
    <limit
      lower="0"
      upper="0"
      effort="10"
      velocity="10" />
    <dynamics
      damping="0.1"
      friction="0.1" />
  </joint>
    <!-- LiDAR Sensor -->
  <link name="lidar_link">
    <visual>
      <geometry>
        <cylinder length="0.05" radius="0.03"/>
      </geometry>
      <material name="black">
        <color rgba="0.0 0.0 0.0 1.0"/>
      </material>
    </visual>
    <collision>
      <geometry>
        <cylinder length="0.05" radius="0.03"/>
      </geometry>
    </collision>
    <inertial>
      <mass value="0.1"/>
      <origin xyz="0 0 0"/>
      <inertia ixx="0.001" ixy="0.0" ixz="0.0" iyy="0.001" iyz="0.0" izz="0.001"/>
    </inertial>
  </link>

  <joint name="lidar_joint" type="fixed">
    <parent link="base_link"/>
    <child link="lidar_link"/>
    <origin xyz="0.4 0 0.07" rpy="0 0 0"/>
  </joint>

  <!-- Camera -->
  <link name="camera_link">
    <collision>
      <origin xyz="-0.05 0 -0.01" rpy="0 0 0"/>
      <geometry>
    <box size="0.05 0.05 0.05"/>
      </geometry>
    </collision>

    <visual>
      <origin xyz="-0.05 0 -0.01" rpy="0 0 0"/>
      <geometry>
    <box size="0.05 0.05 0.05"/>
      </geometry>
      <material name="gray"/>
    </visual>

    <inertial>
      <mass value="1e-5" />
      <origin xyz="0 0 0" rpy="0 0 0"/>
      <inertia ixx="1e-6" ixy="0" ixz="0" iyy="1e-6" iyz="0" izz="1e-6" />
    </inertial>
  </link>
  <joint name="camera_joint" type="fixed">
    <axis xyz="0 1 0" />
    <origin xyz="0.5 0 -0.01" rpy="0 0 0"/>
    <parent link="base_link"/>
    <child link="camera_link"/>
  </joint>
  <transmission name="arm_1_joint_transmission">
    <type>transmission_interface/SimpleTransmission</type>
    <joint name="joint_1">
      <hardwareInterface>hardware_interface/PositionJointInterface</hardwareInterface>
    </joint>
    <actuator name="link1">
      <mechanicalReduction>1.0</mechanicalReduction>
    </actuator>
  </transmission>

  <transmission name="arm_2_joint_transmission">
    <type>transmission_interface/SimpleTransmission</type>
    <joint name="joint_2">
      <hardwareInterface>hardware_interface/PositionJointInterface</hardwareInterface>
    </joint>
    <actuator name="link2">
      <mechanicalReduction>1.0</mechanicalReduction>
    </actuator>
  </transmission>

<gazebo>
  <plugin name="differential_drive_controller" filename="libgazebo_ros_diff_drive.so">

    <!-- Plugin update rate in Hz -->
    <updateRate>10</updateRate>

    <!-- Name of left joint, defaults to `left_joint` -->
    <leftJoint>left_joint_car</leftJoint>

    <!-- Name of right joint, defaults to `right_joint` -->
    <rightJoint>right_joint_car</rightJoint>

    <!-- The distance from the center of one wheel to the other, in meters, defaults to 0.34 m -->
    <wheelSeparation>0.5380</wheelSeparation>

    <!-- Diameter of the wheels, in meters, defaults to 0.15 m -->
    <wheelDiameter>0.2410</wheelDiameter>

    <!-- Wheel acceleration, in rad/s^2, defaults to 0.0 rad/s^2 -->
    <wheelAcceleration>1.0</wheelAcceleration>

    <!-- Maximum torque which the wheels can produce, in Nm, defaults to 5 Nm -->
    <wheelTorque>20</wheelTorque>

    <!-- Topic to receive geometry_msgs/Twist message commands, defaults to `cmd_vel` -->
    <commandTopic>cmd_vel</commandTopic>

    <!-- Topic to publish nav_msgs/Odometry messages, defaults to `odom` -->
    <odometryTopic>odom</odometryTopic>

    <!-- Odometry frame, defaults to `odom` -->
    <odometryFrame>odom</odometryFrame>

    <!-- Robot frame to calculate odometry from, defaults to `base_footprint` -->
    <robotBaseFrame>base_link</robotBaseFrame>

    <!-- Odometry source, 0 for ENCODER, 1 for WORLD, defaults to WORLD -->
    <odometrySource>1</odometrySource>

    <!-- Set to true to publish transforms for the wheel links, defaults to false -->
    <publishWheelTF>false</publishWheelTF>

    <!-- Set to true to publish transforms for the odometry, defaults to true -->
    <publishOdom>true</publishOdom>

    <!-- Set to true to publish sensor_msgs/JointState on /joint_states for the wheel joints, defaults to false -->
    <publishWheelJointState>true</publishWheelJointState>

    <!-- Set to true to swap right and left wheels, defaults to true -->
    <legacyMode>false</legacyMode>
  </plugin>
</gazebo>
<!-- hokuyo -->
  <gazebo reference="lidar_link">
    <sensor type="ray" name="head_hokuyo_sensor">
      <pose>0 0 0 0 0 0</pose>
      <visualize>true</visualize>
      <update_rate>30</update_rate>
      <ray>
        <scan>
          <horizontal>
            <samples>720</samples>
            <resolution>1</resolution>
            <min_angle>-1.57</min_angle>
            <max_angle>1.57</max_angle>
          </horizontal>
        </scan>
        <range>
          <min>0.10</min>
          <max>20.0</max>
          <resolution>0.01</resolution>
        </range>
        <noise>
          <type>gaussian</type>
          <!-- Noise parameters based on published spec for Hokuyo laser
                achieving "+-30mm" accuracy at range < 10m.  A mean of 0.0m and
                stddev of 0.01m will put 99.7% of samples within 0.03m of the true
                reading. -->
          <mean>0.0</mean>
          <stddev>0.01</stddev>
        </noise>
      </ray>
      <plugin name="gazebo_ros_head_hokuyo_controller" filename="libgazebo_ros_laser.so">
        <topicName>/rrbot/laser/scan</topicName>
        <frameName>lidar_link</frameName>
      </plugin>
    </sensor>
  </gazebo>
  <!-- camera -->
<gazebo reference="camera_link">
  <material>Gazebo/Red</material>

  <sensor name="camera" type="camera">
      <pose> 0 0 0 0 0 0 </pose>
      <visualize>true</visualize>
      <update_rate>10</update_rate>
      <camera>
          <horizontal_fov>1.089</horizontal_fov>
          <image>
              <format>R8G8B8</format>
              <width>640</width>
              <height>480</height>
          </image>
          <clip>
              <near>0.05</near>
              <far>8.0</far>
          </clip>
      </camera>
      <plugin name="camera_controller" filename="libgazebo_ros_camera.so">
          <frame_name>camera_link_optical</frame_name>
      </plugin>
  </sensor>
</gazebo>
  
<gazebo>
  <plugin name="gps_plugin" filename="libhector_gazebo_ros_gps.so">
    <alwaysOn>true</alwaysOn>
    <updateRate>10.0</updateRate>
    <bodyName>base_link</bodyName> <!-- Link gắn GPS -->
    <topicName>/gps/fix</topicName>
    <velocityTopicName>/gps/fix_velocity</velocityTopicName>
    <referenceLatitude>21.028511</referenceLatitude>
    <referenceLongitude>105.804817</referenceLongitude>
    <referenceAltitude>10.0</referenceAltitude>
    <drift>0.001 0.001 0.001</drift>
    <gaussianNoise>0.05 0.05 0.05</gaussianNoise>
  </plugin>
</gazebo>
<gazebo>
  <plugin name="gazebo_ros_control" filename="libgazebo_ros_control.so">
    <robotNamespace>/</robotNamespace>
    <robotSimType>gazebo_ros_control/DefaultRobotHWSim</robotSimType>
    <legacyModeNS>false</legacyModeNS>
    <controlPeriod>0.001</controlPeriod>
  </plugin>
</gazebo>
</robot>
